<?xml version="1.0" ?>
<robot name="neon" xmlns:xacro="http://www.ros.org/wiki/xacro">

<xacro:include filename="$(find neon_description)/urdf/materials.xacro" />
<xacro:include filename="$(find neon_description)/urdf/neon.trans" />
<xacro:include filename="$(find neon_description)/urdf/neon.gazebo" />
<link name="base_link">
  <inertial>
    <origin xyz="-0.00039422277255785987 1.084780495821391e-17 0.030860265591493685" rpy="0 0 0"/>
    <mass value="3.2907733114760065"/>
    <inertia ixx="0.002996" iyy="0.005426" izz="0.007902" ixy="0.0" iyz="0.0" ixz="-1.4e-05"/>
  </inertial>
  <visual>
    <origin xyz="0 0 0" rpy="0 0 0"/>
    <geometry>
      <mesh filename="file://$(find neon_description)/meshes/base_link.stl" scale="0.001 0.001 0.001"/>
    </geometry>
    <material name="silver"/>
  </visual>
  <collision>
    <origin xyz="0 0 0" rpy="0 0 0"/>
    <geometry>
      <mesh filename="file://$(find neon_description)/meshes/base_link.stl" scale="0.001 0.001 0.001"/>
    </geometry>
  </collision>
</link>

<link name="left_wheel_1">
  <inertial>
    <origin xyz="-1.0408340855860843e-17 0.009999999999999988 -6.938893903907228e-18" rpy="0 0 0"/>
    <mass value="0.3082687791334984"/>
    <inertia ixx="5.8e-05" iyy="9.6e-05" izz="5.8e-05" ixy="-0.0" iyz="0.0" ixz="-0.0"/>
  </inertial>
  <visual>
    <origin xyz="-0.025 -0.055 -0.026" rpy="0 0 0"/>
    <geometry>
      <mesh filename="file://$(find neon_description)/meshes/left_wheel_1.stl" scale="0.001 0.001 0.001"/>
    </geometry>
    <material name="silver"/>
  </visual>
  <collision>
    <origin xyz="-0.025 -0.055 -0.026" rpy="0 0 0"/>
    <geometry>
      <mesh filename="file://$(find neon_description)/meshes/left_wheel_1.stl" scale="0.001 0.001 0.001"/>
    </geometry>
  </collision>
</link>

<link name="right_wheel_1">
  <inertial>
    <origin xyz="-6.938893903907228e-18 -0.009999999999999988 -3.469446951953614e-18" rpy="0 0 0"/>
    <mass value="0.3082687791334984"/>
    <inertia ixx="5.8e-05" iyy="9.6e-05" izz="5.8e-05" ixy="0.0" iyz="0.0" ixz="-0.0"/>
  </inertial>
  <visual>
    <origin xyz="-0.025 0.055 -0.026" rpy="0 0 0"/>
    <geometry>
      <mesh filename="file://$(find neon_description)/meshes/right_wheel_1.stl" scale="0.001 0.001 0.001"/>
    </geometry>
    <material name="silver"/>
  </visual>
  <collision>
    <origin xyz="-0.025 0.055 -0.026" rpy="0 0 0"/>
    <geometry>
      <mesh filename="file://$(find neon_description)/meshes/right_wheel_1.stl" scale="0.001 0.001 0.001"/>
    </geometry>
  </collision>
</link>

<link name="lidar_1">
  <inertial>
    <origin xyz="0.0 3.769546289141946e-18 0.007500000000000007" rpy="0 0 0"/>
    <mass value="0.14796901398407922"/>
    <inertia ixx="1.8e-05" iyy="1.8e-05" izz="3e-05" ixy="0.0" iyz="0.0" ixz="0.0"/>
  </inertial>
  <visual>
    <origin xyz="0.04 -0.0 -0.051" rpy="0 0 0"/>
    <geometry>
      <mesh filename="file://$(find neon_description)/meshes/lidar_1.stl" scale="0.001 0.001 0.001"/>
    </geometry>
    <material name="silver"/>
  </visual>
  <collision>
    <origin xyz="0.04 -0.0 -0.051" rpy="0 0 0"/>
    <geometry>
      <mesh filename="file://$(find neon_description)/meshes/lidar_1.stl" scale="0.001 0.001 0.001"/>
    </geometry>
  </collision>
</link>

<joint name="Revolute 1" type="continuous">
  <origin xyz="0.025 0.055 0.026" rpy="0 0 0"/>
  <parent link="base_link"/>
  <child link="left_wheel_1"/>
  <axis xyz="0.0 1.0 0.0"/>
</joint>

<joint name="Revolute 2" type="continuous">
  <origin xyz="0.025 -0.055 0.026" rpy="0 0 0"/>
  <parent link="base_link"/>
  <child link="right_wheel_1"/>
  <axis xyz="0.0 -1.0 0.0"/>
</joint>

<joint name="Rigid 3" type="fixed">
  <origin xyz="-0.04 0.0 0.051" rpy="0 0 0"/>
  <parent link="base_link"/>
  <child link="lidar_1"/>
</joint>

</robot>
